Workbook
Name OP_prob: 'PARÁMETROS'!$D$11:$H$11
Name p_o: 'PARÁMETROS'!$C$18:$C$22
Name CC_L: 'PARÁMETROS'!$L$38:$N$38
Name CC_SA: 'PARÁMETROS'!$L$29:$N$29
Name FR_G: 'PARÁMETROS'!$BH$3:$BH$30
Name FC_G: 'PARÁMETROS'!$BJ$3:$BJ$30
Name FC_FI: 'PARÁMETROS'!$BZ$3:$BZ$30
Name FR_SE: 'PARÁMETROS'!$R$3:$R$46
Name FC_DS: 'PARÁMETROS'!$BB$3:$BB$26
Name FV_OP: 'PARÁMETROS'!$BT$3:$BT$11
Name JC_SE: 'PARÁMETROS'!$K$3:$K$8
Name FP_SE: 'PARÁMETROS'!$P$3:$P$45
Name FV_MA: 'PARÁMETROS'!$AF$3:$AF$12
Name FP_G: 'PARÁMETROS'!$BF$3:$BF$30
Name JC_DS: 'PARÁMETROS'!$K$12:$K$17
Name FV_L: 'PARÁMETROS'!$AV$3:$AV$30
Name FV_G: 'PARÁMETROS'!$BL$3:$BL$30
Name JC_SA: 'PARÁMETROS'!$K$30:$K$35
Name FI_MA: 'PARÁMETROS'!$AB$3:$AB$29
Name CC_SE: 'PARÁMETROS'!$L$2:$N$2
Name CC_G: 'PARÁMETROS'!$L$47:$N$47
Name FV_SA: 'PARÁMETROS'!$AN$3:$AN$30
Name FV_DS: 'PARÁMETROS'!$BD$3:$BD$7
Name FC_L: 'PARÁMETROS'!$AT$3:$AT$30
Name FR_L: 'PARÁMETROS'!$AR$3:$AR$30
Name FR_SA: 'PARÁMETROS'!$AJ$3:$AJ$30
Name VS: 'PARÁMETROS'!$X$3:$X$22
Name JC_G: 'PARÁMETROS'!$K$48:$K$53
Name FC_SE: 'PARÁMETROS'!$T$3:$T$19
Name Op_Sev: 'PARÁMETROS'!$C$12:$C$16
Name CC_DS: 'PARÁMETROS'!$L$11:$N$11
Name FP_FI: 'PARÁMETROS'!$BV$3:$BV$30
Name FP_SA: 'PARÁMETROS'!$AH$3:$AH$30
Name FP_op: 'PARÁMETROS'!$BN$3:$BN$10
Name JC_FI: 'PARÁMETROS'!$K$66:$K$71
Name JC_L: 'PARÁMETROS'!$K$39:$K$44
Name FR_FI: 'PARÁMETROS'!$BX$3:$BX$30
Name FV_FI: 'PARÁMETROS'!$CB$3:$CB$30
Name CC_MA: 'PARÁMETROS'!$L$20:$N$20
Name Oportunidad: 'PARÁMETROS'!$D$12:$H$16
Name JC_OP: 'PARÁMETROS'!$K$57:$K$62
Name FR_OP: 'PARÁMETROS'!$BP$3:$BP$11
Name FC_MA: 'PARÁMETROS'!$AD$3:$AD$35
Name JC_MA: 'PARÁMETROS'!$K$21:$K$26
Name FV_SE: 'PARÁMETROS'!$V$3:$V$8
Name FR_DS: 'PARÁMETROS'!$AZ$3:$AZ$16
Name CC_FI: 'PARÁMETROS'!$L$65:$N$65
Name FC_SA: 'PARÁMETROS'!$AL$3:$AL$30
Name CC_OP: 'PARÁMETROS'!$L$56:$N$56
Name FP_DS: 'PARÁMETROS'!$AX$3:$AX$24
Name FP_L: 'PARÁMETROS'!$AP$3:$AP$30
Name FA_MA: 'PARÁMETROS'!$Z$3:$Z$46
Name FC_OP: 'PARÁMETROS'!$BR$3:$BR$11

Sheet MATRIZ DE RIESGOS_2024
D1: IDENTIFICACIÓN, EVALUACIÓN DE RIESGOS | W1: 1.02.P06.F01
W2: INTERNA
A3: Gerencia / Superintendencia Senior : | E3: GERENCIA DE MANTENIMIENTO Y SERVICIOS DE SOPORTE | P3: Elaborador por : | Q3: Erick Muñoz Arandia | S3: Revisado y aprobado por : | T3: MIGUEL MARTIN RUBIN DE CELIS CANDIA
A4: Superintendencia : | E4: SUPERINTENDENCIA DE MANTENIMIENTO - MEC. PLANTA CHANCADO, MOLIENDA Y LUBRICACION
A5: Área / Departamento : | E5: Mantenimiento Chancado | P5: Fecha : | Q5: 05 / Dic / 2024 | S5: Fecha: | T5: 02 / Ene / 2025
A6: N° | B6: Área / Proceso / Alcance | C6: Actividad / Tarea / Grupo de Interés | D6: Condición Normal, Anormal, Emergencia o Factor | E6: Seguridad, Salud, Medio Ambiente, Legal, Responsabilidad Social, Otro | F6: Familia Peligro/ Aspecto / Evento | G6: Descripción Peligro / Aspecto / Evento | H6: Familia Riesgo / Impacto / Consecuencia | I6: Descripción Riesgo / Impacto / Coonsecuencia | J6: Riesgo / Impacto | P6: Familia de Controles | Q6: Medidas de Prevención, Control y Mitigación | R6: Familia de Verificadores | S6: Verificadores | T6: Calidad del Control | U6: Jerarquía de Control | V6: Eficacia del Control / Acción | W6: Nivel de Riesgo / Impacto Actual | X6: Incidentes Ocurridos | Y6: Trazabilidad / Historial / Observaciones Actual
J7: Exposición | K7: Posibilidad | L7: Probabilidad (R/I) | M7: Severidad | N7: Resultado de Evaluación Riesgo / Iimpacto | O7: Nivel de Riesgo / Iimpacto Inicial Puro
A8: 1 | B8: Mantenimiento Chancador | C8: Desmontaje y montaje de componentes del Chancador Primario (araña, cóncavos, eje principal) | D8: Normal | E8: Seguridad | F8: Trabajo / circulación de equipo/vehículo (pesado / liviano) | G8: Equipo de mina en operación, en el área de trabajo | H8: Aplastamiento | I8: Atropellamiento con equipo de operación minera que circulan por el chancador | J8: 5 | K8: 2 | L8: =IF(OR(J8<>"",K8<>""),OFFSET('PARÁMETROS'!$B$2,K8,J8),"") -> 3 | M8: 5 | N8: =IFERROR(L8*M8,"") -> 15 | O8: =IF(N8="","",IFERROR(IF(N8<=2,"ACEPTABLE",IF(N8<=6,"BAJA",IF(N8<=10,"ACEPTABLE CON REVISIÓN",IF(N8<=15,"SUSTANCIAL","INACEPTABLE")))),"")) -> SUSTANCIAL | P8: Señales/ Advertencias/ Alarmas | Q8: Señalizar con Conos de Seguridad y letrero de Camino Cerrado durante trabajos de Mantenimiento de Chancador | R8: Publicación de Indicadores | S8: Seguimiento y publicación de reporte STOP o Seguimiento y publicación de reporte de observaciones conductuales | T8: A. Mayor 80% | U8: 3. Señalización/ Advertencias/ Alarma | V8: =IFERROR(IF(AA8="SEGURIDAD",OFFSET('PARÁMETROS'!$K$2,MATCH(U8,JC_SE,0),MATCH(T8,CC_SE,0)), IF(OR(AA8="DSRC/Estratégico",AA8="DSRC/Operativo"),OFFSET('PARÁMETROS'!$K$11,MATCH(U8,JC_DS,0),MATCH(T8,CC_DS,0)), IF(AA8="SALUD",OFFSET('PARÁMETROS'!$K$29,MATCH(U8,JC_SA,0),MATCH(T8,CC_SA,0)), IF(AA8="MEDIO AMBIENTE",OFFSET('PARÁMETROS'!$K$20,MATCH(U8,JC_MA,0),MATCH(T8,CC_MA,0)), IF(AA8="Rel. Gubernamentales",OFFSET('PARÁMETROS'!$K$48,MATCH(U8,JC_G,0),MATCH(T8,CC_G,0)), IF(AA8="OPERACIONAL",OFFSET('PARÁMETROS'!$K$56,MATCH(U8,JC_OP,0),MATCH(T8,CC_OP,0)), IF(AA8="FINANCIERO",OFFSET('PARÁMETROS'!$K$56,MATCH(U8,JC_FI,0),MATCH(T8,CC_FI,0)), OFFSET('PARÁMETROS'!$K$38,MATCH(U8,JC_L,0),MATCH(T8,CC_L,0))))))))),"") -> Control/Acción Eficaz | W8: =IF(E8="","", IF(COUNTA( V8)-COUNTBLANK( V8)=1, IF(O8="INACEPTABLE",IF(COUNTIF( V8,"Control/Acción Eficaz")>=1,"SUSTANCIAL","INACEPTABLE"), IF(O8="SUSTANCIAL",IF(COUNTIF( V8,"Control/Acción Eficaz")>=1,"ACEPTABLE CON REVISIÓN","SUSTANCIAL"), IF(O8="ACEPTABLE CON REVISIÓN",IF(COUNTIF( V8,"Control/Acción Eficaz")>=1,"BAJA","ACEPTABLE CON REVISIÓN"), IF(O8="BAJA",IF(COUNTIF( V8,"Control/Acción Eficaz")>=1,"ACEPTABLE","BAJA"),)))), IF(COUNTA( V8)-COUNTBLANK( V8)=2, IF(O8="INACEPTABLE",IF(COUNTIF( V8,"Control/Acción Eficaz")=2,"ACEPTABLE CON REVISIÓN", IF(OR(AND(COUNTIF( V8,"Control/Acción Eficaz")=1,COUNTIF( V8,"Control/Acción Satisfactorio")=1), AND(COUNTIF( V8,"Control/Acción Eficaz")=1,COUNTIF( V8,"Control/Acción No Eficaz")=1)),"SUSTANCIAL","INACEPTABLE")), IF(O8="SUSTANCIAL",IF(COUNTIF( V8,"Control/Acción Eficaz")=2,"BAJA", IF(OR(AND(COUNTIF( V8,"Control/Acción Eficaz")=1,COUNTIF( V8,"Control/Acción Satisfactorio")=1), AND(COUNTIF( V8,"Control/Acción Eficaz")=1,COUNTIF( V8,"Control/Acción No Eficaz")=1)),"ACEPTABLE CON REVISIÓN ","SUSTANCIAL")), IF(O8="ACEPTABLE CON REVISIÓN",IF(COUNTIF( V8,"Control/Acción Eficaz")=2,"ACEPTABLE", IF(OR(AND(COUNTIF( V8,"Control/Acción Eficaz")=1,COUNTIF( V8,"Control/Acción Satisfactorio")=1), AND(COUNTIF( V8,"Control/Acción Eficaz")=1,COUNTIF( V8,"Control/Acción No Eficaz")=1)),"BAJA","ACEPTABLE CON REVISIÓN")), IF(O8="BAJA",IF(COUNTIF( V8,"Control/Acción Eficaz")>=2,"ACEPTABLE","BAJA"),)))), IF(COUNTA( V8)-COUNTBLANK( V8)>=3, IF(O8="INACEPTABLE", IF(COUNTBLANK( V8)=COUNTA( V8),"", IF(COUNTIF( V8,"Control/Acción No Eficaz")>=2,"INACEPTABLE", IF(AND(COUNTIF( V8,"Control/Acción No Eficaz")=0,COUNTIF( V8,"Control/Acción Eficaz")>=2),"ACEPTABLE CON REVISIÓN ","SUSTANCIAL"))), IF(O8="SUSTANCIAL", IF(COUNTBLANK( V8)=COUNTA( V8),"", IF(COUNTIF( V8,"Control/Acción No Eficaz")>=2,"SUSTANCIAL", IF(AND(COUNTIF( V8,"Control/Acción No Eficaz")=0,COUNTIF( V8,"Control/Acción Eficaz")>=2),"BAJA","ACEPTABLE CON REVISIÓN"))), IF(O8="ACEPTABLE CON REVISIÓN", IF(COUNTBLANK( V8)=COUNTA( V8),"", IF(COUNTIF( V8,"Control/Acción No Eficaz")>=2,"ACEPTABLE CON REVISIÓN", IF(AND(COUNTIF( V8,"Control/Acción No Eficaz")=0,COUNTIF( V8,"Control/Acción Eficaz")>=2),"ACEPTABLE","BAJA"))), IF(O8="BAJA", IF(COUNTBLANK( V8)=COUNTA( V8),"", IF(AND(COUNTBLANK( V8)<1,COUNTA( V8)=1), IF(COUNTIF( V8,"Control/Acción No Eficaz")>=2,"BAJA", IF(AND(COUNTIF( V8,"Control/Acción No Eficaz")=0,COUNTIF( V8,"Control/Acción Eficaz")>=2),"ACEPTABLE","BAJA")), IF(COUNTIF( V8,"Control/Acción No Eficaz")>=2,"BAJA", IF(AND(COUNTIF( V8,"Control/Acción No Eficaz")=0,COUNTIF( V8,"Control/Acción Eficaz")>=2),"ACEPTABLE","BAJA")))), IF(COUNTIF( V8,"")>=5,"",O8))))), "")))) -> ACEPTABLE CON REVISIÓN | Z8: OK | AA8: =E8 -> Seguridad
A9: 2 | B9: Mantenimiento Chancador | C9: Desmontaje y montaje de componentes del Chancador Primario (araña, cóncavos, eje principal) | D9: Normal | E9: Seguridad | F9: Trabajo en altura, sobre plataformas elevadas, escaleras, andamios, rampas o pisos sin barreras de protección (barandas o barreras rígidas). | G9: Trabajo en altura cerca del perímetro del buzón de descarga parte superior, montaje y desmontaje de componentes de chancador primario | H9: Caída de altura (Igual o Mayor a 1,80) | I9: Al realizar trabajos en la parte superior del buzón existe el riesgo de caída a distinto nivel | J9: 3 | K9: 2 | L9: =IF(OR(J9<>"",K9<>""),OFFSET('PARÁMETROS'!$B$2,K9,J9),"") -> 4 | M9: 5 | N9: =IFERROR(L9*M9,"") -> 20 | O9: =IF(N9="","",IFERROR(IF(N9<=2,"ACEPTABLE",IF(N9<=6,"BAJA",IF(N9<=10,"ACEPTABLE CON REVISIÓN",IF(N9<=15,"SUSTANCIAL","INACEPTABLE")))),"")) -> INACEPTABLE | P9: Competencias | Q9: Contar con personal competente para realizar Trabajo en Altura | R9: Planillas de vigencia de Certificaciones / Competencias/ Capacitaciones | S9: Seguimiento a la Planilla de vigencia de cursos, autorizaciones, competencias y/o certificaciones de personas y equipos | T9: A. Mayor 80% | U9: 2. Administrativo/ Procedimientos/ Capacitación | V9: =IFERROR(IF(AA9="SEGURIDAD",OFFSET('PARÁMETROS'!$K$2,MATCH(U9,JC_SE,0),MATCH(T9,CC_SE,0)), IF(OR(AA9="DSRC/Estratégico",AA9="DSRC/Operativo"),OFFSET('PARÁMETROS'!$K$11,MATCH(U9,JC_DS,0),MATCH(T9,CC_DS,0)), IF(AA9="SALUD",OFFSET('PARÁMETROS'!$K$29,MATCH(U9,JC_SA,0),MATCH(T9,CC_SA,0)), IF(AA9="MEDIO AMBIENTE",OFFSET('PARÁMETROS'!$K$20,MATCH(U9,JC_MA,0),MATCH(T9,CC_MA,0)), IF(AA9="Rel. Gubernamentales",OFFSET('PARÁMETROS'!$K$48,MATCH(U9,JC_G,0),MATCH(T9,CC_G,0)), IF(AA9="OPERACIONAL",OFFSET('PARÁMETROS'!$K$56,MATCH(U9,JC_OP,0),MATCH(T9,CC_OP,0)), IF(AA9="FINANCIERO",OFFSET('PARÁMETROS'!$K$56,MATCH(U9,JC_FI,0),MATCH(T9,CC_FI,0)), OFFSET('PARÁMETROS'!$K$38,MATCH(U9,JC_L,0),MATCH(T9,CC_L,0))))))))),"") -> Control/Acción Eficaz | W9: =IF(E9="","", IF(COUNTA( V9:V26)-COUNTBLANK( V9:V26)=1, IF(O9="INACEPTABLE",IF(COUNTIF( V9:V26,"Control/Acción Eficaz")>=1,"SUSTANCIAL","INACEPTABLE"), IF(O9="SUSTANCIAL",IF(COUNTIF( V9:V26,"Control/Acción Eficaz")>=1,"ACEPTABLE CON REVISIÓN","SUSTANCIAL"), IF(O9="ACEPTABLE CON REVISIÓN",IF(COUNTIF( V9:V26,"Control/Acción Eficaz")>=1,"BAJA","ACEPTABLE CON REVISIÓN"), IF(O9="BAJA",IF(COUNTIF( V9:V26,"Control/Acción Eficaz")>=1,"ACEPTABLE","BAJA"),)))), IF(COUNTA( V9:V26)-COUNTBLANK( V9:V26)=2, IF(O9="INACEPTABLE",IF(COUNTIF( V9:V26,"Control/Acción Eficaz")=2,"ACEPTABLE CON REVISIÓN", IF(OR(AND(COUNTIF( V9:V26,"Control/Acción Eficaz")=1,COUNTIF( V9:V26,"Control/Acción Satisfactorio")=1), AND(COUNTIF( V9:V26,"Control/Acción Eficaz")=1,COUNTIF( V9:V26,"Control/Acción No Eficaz")=1)),"SUSTANCIAL","INACEPTABLE")), IF(O9="SUSTANCIAL",IF(COUNTIF( V9:V26,"Control/Acción Eficaz")=2,"BAJA", IF(OR(AND(COUNTIF( V9:V26,"Control/Acción Eficaz")=1,COUNTIF( V9:V26,"Control/Acción Satisfactorio")=1), AND(COUNTIF( V9:V26,"Control/Acción Eficaz")=1,COUNTIF( V9:V26,"Control/Acción No Eficaz")=1)),"ACEPTABLE CON REVISIÓN ","SUSTANCIAL")), IF(O9="ACEPTABLE CON REVISIÓN",IF(COUNTIF( V9:V26,"Control/Acción Eficaz")=2,"ACEPTABLE", IF(OR(AND(COUNTIF( V9:V26,"Control/Acción Eficaz")=1,COUNTIF( V9:V26,"Control/Acción Satisfactorio")=1), AND(COUNTIF( V9:V26,"Control/Acción Eficaz")=1,COUNTIF( V9:V26,"Control/Acción No Eficaz")=1)),"BAJA","ACEPTABLE CON REVISIÓN")), IF(O9="BAJA",IF(COUNTIF( V9:V26,"Control/Acción Eficaz")>=2,"ACEPTABLE","BAJA"),)))), IF(COUNTA( V9:V26)-COUNTBLANK( V9:V26)>=3, IF(O9="INACEPTABLE", IF(COUNTBLANK( V9:V26)=COUNTA( V9:V26),"", IF(COUNTIF( V9:V26,"Control/Acción No Eficaz")>=2,"INACEPTABLE", IF(AND(COUNTIF( V9:V26,"Control/Acción No Eficaz")=0,COUNTIF( V9:V26,"Control/Acción Eficaz")>=2),"ACEPTABLE CON REVISIÓN ","SUSTANCIAL"))), IF(O9="SUSTANCIAL", IF(COUNTBLANK( V9:V26)=COUNTA( V9:V26),"", IF(COUNTIF( V9:V26,"Control/Acción No Eficaz")>=2,"SUSTANCIAL", IF(AND(COUNTIF( V9:V26,"Control/Acción No Eficaz")=0,COUNTIF( V9:V26,"Control/Acción Eficaz")>=2),"BAJA","ACEPTABLE CON REVISIÓN"))), IF(O9="ACEPTABLE CON REVISIÓN", IF(COUNTBLANK( V9:V26)=COUNTA( V9:V26),"", IF(COUNTIF( V9:V26,"Control/Acción No Eficaz")>=2,"ACEPTABLE CON REVISIÓN", IF(AND(COUNTIF( V9:V26,"Control/Acción No Eficaz")=0,COUNTIF( V9:V26,"Control/Acción Eficaz")>=2),"ACEPTABLE","BAJA"))), IF(O9="BAJA", IF(COUNTBLANK( V9:V26)=COUNTA( V9:V26),"", IF(AND(COUNTBLANK( V9:V26)<1,COUNTA( V9:V26)=1), IF(COUNTIF( V9:V26,"Control/Acción No Eficaz")>=2,"BAJA", IF(AND(COUNTIF( V9:V26,"Control/Acción No Eficaz")=0,COUNTIF( V9:V26,"Control/Acción Eficaz")>=2),"ACEPTABLE","BAJA")), IF(COUNTIF( V9:V26,"Control/Acción No Eficaz")>=2,"BAJA", IF(AND(COUNTIF( V9:V26,"Control/Acción No Eficaz")=0,COUNTIF( V9:V26,"Control/Acción Eficaz")>=2),"ACEPTABLE","BAJA")))), IF(COUNTIF( V9:V26,"")>=5,"",O9))))), "")))) -> SUSTANCIAL | Z9: OK | AA9: =E9 -> Seguridad
P10: Capacitación/Entrenamiento | Q10: Capacitar al personal sobre los estándares del Instructivo de Trabajo en Altura 1.02.P06.I15 | R10: Planes / Programas | S10: Seguimiento al programa de difusión de instructivos y capacitaciones internas | T10: B. 50% y 80% | U10: 2. Administrativo/ Procedimientos/ Capacitación | V10: =IFERROR(IF(AA10="SEGURIDAD",OFFSET('PARÁMETROS'!$K$2,MATCH(U10,JC_SE,0),MATCH(T10,CC_SE,0)), IF(OR(AA10="DSRC/Estratégico",AA10="DSRC/Operativo"),OFFSET('PARÁMETROS'!$K$11,MATCH(U10,JC_DS,0),MATCH(T10,CC_DS,0)), IF(AA10="SALUD",OFFSET('PARÁMETROS'!$K$29,MATCH(U10,JC_SA,0),MATCH(T10,CC_SA,0)), IF(AA10="MEDIO AMBIENTE",OFFSET('PARÁMETROS'!$K$20,MATCH(U10,JC_MA,0),MATCH(T10,CC_MA,0)), IF(AA10="Rel. Gubernamentales",OFFSET('PARÁMETROS'!$K$48,MATCH(U10,JC_G,0),MATCH(T10,CC_G,0)), IF(AA10="OPERACIONAL",OFFSET('PARÁMETROS'!$K$56,MATCH(U10,JC_OP,0),MATCH(T10,CC_OP,0)), IF(AA10="FINANCIERO",OFFSET('PARÁMETROS'!$K$56,MATCH(U10,JC_FI,0),MATCH(T10,CC_FI,0)), OFFSET('PARÁMETROS'!$K$38,MATCH(U10,JC_L,0),MATCH(T10,CC_L,0))))))))),"") -> Control/Acción Satisfactorio | Z10: OK | AA10: =E9 -> Seguridad
P11: Capacitación/Entrenamiento | Q11: Contar con Personal con curso vigente en Gestión de Riesgos (ART/VPT) | R11: Planillas de vigencia de Certificaciones / Competencias/ Capacitaciones | S11: Seguimiento a la Planilla de vigencia de cursos, autorizaciones, competencias y/o certificaciones de personas y equipos | T11: A. Mayor 80% | U11: 2. Administrativo/ Procedimientos/ Capacitación | V11: =IFERROR(IF(AA11="SEGURIDAD",OFFSET('PARÁMETROS'!$K$2,MATCH(U11,JC_SE,0),MATCH(T11,CC_SE,0)), IF(OR(AA11="DSRC/Estratégico",AA11="DSRC/Operativo"),OFFSET('PARÁMETROS'!$K$11,MATCH(U11,JC_DS,0),MATCH(T11,CC_DS,0)), IF(AA11="SALUD",OFFSET('PARÁMETROS'!$K$29,MATCH(U11,JC_SA,0),MATCH(T11,CC_SA,0)), IF(AA11="MEDIO AMBIENTE",OFFSET('PARÁMETROS'!$K$20,MATCH(U11,JC_MA,0),MATCH(T11,CC_MA,0)), IF(AA11="Rel. Gubernamentales",OFFSET('PARÁMETROS'!$K$48,MATCH(U11,JC_G,0),MATCH(T11,CC_G,0)), IF(AA11="OPERACIONAL",OFFSET('PARÁMETROS'!$K$56,MATCH(U11,JC_OP,0),MATCH(T11,CC_OP,0)), IF(AA11="FINANCIERO",OFFSET('PARÁMETROS'!$K$56,MATCH(U11,JC_FI,0),MATCH(T11,CC_FI,0)), OFFSET('PARÁMETROS'!$K$38,MATCH(U11,JC_L,0),MATCH(T11,CC_L,0))))))))),"") -> Control/Acción Eficaz | Z11: OK | AA11: =E9 -> Seguridad
P12: Capacitación/Entrenamiento | Q12: Capacitar al personal sobre respuesta ante emergencias descrito del Plan de Emergencia 2.04.P05.E20 | R12: Planes / Programas | S12: Seguimiento al programa de difusión de instructivos y capacitaciones internas | T12: B. 50% y 80% | U12: 2. Administrativo/ Procedimientos/ Capacitación | V12: =IFERROR(IF(AA12="SEGURIDAD",OFFSET('PARÁMETROS'!$K$2,MATCH(U12,JC_SE,0),MATCH(T12,CC_SE,0)), IF(OR(AA12="DSRC/Estratégico",AA12="DSRC/Operativo"),OFFSET('PARÁMETROS'!$K$11,MATCH(U12,JC_DS,0),MATCH(T12,CC_DS,0)), IF(AA12="SALUD",OFFSET('PARÁMETROS'!$K$29,MATCH(U12,JC_SA,0),MATCH(T12,CC_SA,0)), IF(AA12="MEDIO AMBIENTE",OFFSET('PARÁMETROS'!$K$20,MATCH(U12,JC_MA,0),MATCH(T12,CC_MA,0)), IF(AA12="Rel. Gubernamentales",OFFSET('PARÁMETROS'!$K$48,MATCH(U12,JC_G,0),MATCH(T12,CC_G,0)), IF(AA12="OPERACIONAL",OFFSET('PARÁMETROS'!$K$56,MATCH(U12,JC_OP,0),MATCH(T12,CC_OP,0)), IF(AA12="FINANCIERO",OFFSET('PARÁMETROS'!$K$56,MATCH(U12,JC_FI,0),MATCH(T12,CC_FI,0)), OFFSET('PARÁMETROS'!$K$38,MATCH(U12,JC_L,0),MATCH(T12,CC_L,0))))))))),"") -> Control/Acción Satisfactorio | Z12: OK | AA12: =E9 -> Seguridad
P13: Controles/Acciones de Emergencias | Q13: Difundir la ruta de evacuación para caso de emergencia, punto de reunión y protocolo de emergencia | R13: Planes / Programas | S13: Seguimiento al programa de reuniones y evaluaciones de compromiso con la seguridad | T13: B. 50% y 80% | U13: 2. Administrativo/ Procedimientos/ Capacitación | V13: =IFERROR(IF(AA13="SEGURIDAD",OFFSET('PARÁMETROS'!$K$2,MATCH(U13,JC_SE,0),MATCH(T13,CC_SE,0)), IF(OR(AA13="DSRC/Estratégico",AA13="DSRC/Operativo"),OFFSET('PARÁMETROS'!$K$11,MATCH(U13,JC_DS,0),MATCH(T13,CC_DS,0)), IF(AA13="SALUD",OFFSET('PARÁMETROS'!$K$29,MATCH(U13,JC_SA,0),MATCH(T13,CC_SA,0)), IF(AA13="MEDIO AMBIENTE",OFFSET('PARÁMETROS'!$K$20,MATCH(U13,JC_MA,0),MATCH(T13,CC_MA,0)), IF(AA13="Rel. Gubernamentales",OFFSET('PARÁMETROS'!$K$48,MATCH(U13,JC_G,0),MATCH(T13,CC_G,0)), IF(AA13="OPERACIONAL",OFFSET('PARÁMETROS'!$K$56,MATCH(U13,JC_OP,0),MATCH(T13,CC_OP,0)), IF(AA13="FINANCIERO",OFFSET('PARÁMETROS'!$K$56,MATCH(U13,JC_FI,0),MATCH(T13,CC_FI,0)), OFFSET('PARÁMETROS'!$K$38,MATCH(U13,JC_L,0),MATCH(T13,CC_L,0))))))))),"") -> Control/Acción Satisfactorio | Z13: OK | AA13: =E9 -> Seguridad
P14: Controles de Ingeniería | Q14: Contar con radio comunicación o Handy en las área de trabajo | R14: Publicación de Indicadores | S14: Seguimiento y publicación de reporte STOP o Seguimiento y publicación de reporte de observaciones conductuales | T14: B. 50% y 80% | U14: 4. Ingeniería | V14: =IFERROR(IF(AA14="SEGURIDAD",OFFSET('PARÁMETROS'!$K$2,MATCH(U14,JC_SE,0),MATCH(T14,CC_SE,0)), IF(OR(AA14="DSRC/Estratégico",AA14="DSRC/Operativo"),OFFSET('PARÁMETROS'!$K$11,MATCH(U14,JC_DS,0),MATCH(T14,CC_DS,0)), IF(AA14="SALUD",OFFSET('PARÁMETROS'!$K$29,MATCH(U14,JC_SA,0),MATCH(T14,CC_SA,0)), IF(AA14="MEDIO AMBIENTE",OFFSET('PARÁMETROS'!$K$20,MATCH(U14,JC_MA,0),MATCH(T14,CC_MA,0)), IF(AA14="Rel. Gubernamentales",OFFSET('PARÁMETROS'!$K$48,MATCH(U14,JC_G,0),MATCH(T14,CC_G,0)), IF(AA14="OPERACIONAL",OFFSET('PARÁMETROS'!$K$56,MATCH(U14,JC_OP,0),MATCH(T14,CC_OP,0)), IF(AA14="FINANCIERO",OFFSET('PARÁMETROS'!$K$56,MATCH(U14,JC_FI,0),MATCH(T14,CC_FI,0)), OFFSET('PARÁMETROS'!$K$38,MATCH(U14,JC_L,0),MATCH(T14,CC_L,0))))))))),"") -> Control/Acción Satisfactorio | Z14: OK | AA14: =E9 -> Seguridad
P15: Capacitación/Entrenamiento | Q15: Capacitar al personal sobre los estándares del Manual de Reglas de Oro, Trabajo en Altura 1.02.P06.MT02. | R15: Planes / Programas | S15: Seguimiento al programa de difusión de instructivos y capacitaciones internas | T15: B. 50% y 80% | U15: 2. Administrativo/ Procedimientos/ Capacitación | V15: =IFERROR(IF(AA15="SEGURIDAD",OFFSET('PARÁMETROS'!$K$2,MATCH(U15,JC_SE,0),MATCH(T15,CC_SE,0)), IF(OR(AA15="DSRC/Estratégico",AA15="DSRC/Operativo"),OFFSET('PARÁMETROS'!$K$11,MATCH(U15,JC_DS,0),MATCH(T15,CC_DS,0)), IF(AA15="SALUD",OFFSET('PARÁMETROS'!$K$29,MATCH(U15,JC_SA,0),MATCH(T15,CC_SA,0)), IF(AA15="MEDIO AMBIENTE",OFFSET('PARÁMETROS'!$K$20,MATCH(U15,JC_MA,0),MATCH(T15,CC_MA,0)), IF(AA15="Rel. Gubernamentales",OFFSET('PARÁMETROS'!$K$48,MATCH(U15,JC_G,0),MATCH(T15,CC_G,0)), IF(AA15="OPERACIONAL",OFFSET('PARÁMETROS'!$K$56,MATCH(U15,JC_OP,0),MATCH(T15,CC_OP,0)), IF(AA15="FINANCIERO",OFFSET('PARÁMETROS'!$K$56,MATCH(U15,JC_FI,0),MATCH(T15,CC_FI,0)), OFFSET('PARÁMETROS'!$K$38,MATCH(U15,JC_L,0),MATCH(T15,CC_L,0))))))))),"") -> Control/Acción Satisfactorio | Z15: OK | AA15: =E9 -> Seguridad
P16: Procedimientos / Instructivos / Reglamentos y otros. | Q16: Cumplir com los estandares del Instructivo de Trabajos en Altura 1.02.P06.I15 | R16: Planes / Programas | S16: Seguimiento al programa de inspecciones IRO´S: Trabajo en Altura | T16: B. 50% y 80% | U16: 2. Administrativo/ Procedimientos/ Capacitación | V16: =IFERROR(IF(AA16="SEGURIDAD",OFFSET('PARÁMETROS'!$K$2,MATCH(U16,JC_SE,0),MATCH(T16,CC_SE,0)), IF(OR(AA16="DSRC/Estratégico",AA16="DSRC/Operativo"),OFFSET('PARÁMETROS'!$K$11,MATCH(U16,JC_DS,0),MATCH(T16,CC_DS,0)), IF(AA16="SALUD",OFFSET('PARÁMETROS'!$K$29,MATCH(U16,JC_SA,0),MATCH(T16,CC_SA,0)), IF(AA16="MEDIO AMBIENTE",OFFSET('PARÁMETROS'!$K$20,MATCH(U16,JC_MA,0),MATCH(T16,CC_MA,0)), IF(AA16="Rel. Gubernamentales",OFFSET('PARÁMETROS'!$K$48,MATCH(U16,JC_G,0),MATCH(T16,CC_G,0)), IF(AA16="OPERACIONAL",OFFSET('PARÁMETROS'!$K$56,MATCH(U16,JC_OP,0),MATCH(T16,CC_OP,0)), IF(AA16="FINANCIERO",OFFSET('PARÁMETROS'!$K$56,MATCH(U16,JC_FI,0),MATCH(T16,CC_FI,0)), OFFSET('PARÁMETROS'!$K$38,MATCH(U16,JC_L,0),MATCH(T16,CC_L,0))))))))),"") -> Control/Acción Satisfactorio | Z16: NO APLICA, PUESTO QUE NO PODRIA INGRESAR AL SECTOR UN EQUIPO DE PLATAFORMA ELEVADORA | AA16: =E9 -> Seguridad
P17: Controles de Ingeniería | Q17: Contar con puntos de anclajes y líneas de vida validados y/o certificados | R17: Planes / Programas | S17: Seguimiento al programa de inspecciones IRO´S: Trabajo en Altura | T17: A. Mayor 80% | U17: 4. Ingeniería | V17: =IFERROR(IF(AA17="SEGURIDAD",OFFSET('PARÁMETROS'!$K$2,MATCH(U17,JC_SE,0),MATCH(T17,CC_SE,0)), IF(OR(AA17="DSRC/Estratégico",AA17="DSRC/Operativo"),OFFSET('PARÁMETROS'!$K$11,MATCH(U17,JC_DS,0),MATCH(T17,CC_DS,0)), IF(AA17="SALUD",OFFSET('PARÁMETROS'!$K$29,MATCH(U17,JC_SA,0),MATCH(T17,CC_SA,0)), IF(AA17="MEDIO AMBIENTE",OFFSET('PARÁMETROS'!$K$20,MATCH(U17,JC_MA,0),MATCH(T17,CC_MA,0)), IF(AA17="Rel. Gubernamentales",OFFSET('PARÁMETROS'!$K$48,MATCH(U17,JC_G,0),MATCH(T17,CC_G,0)), IF(AA17="OPERACIONAL",OFFSET('PARÁMETROS'!$K$56,MATCH(U17,JC_OP,0),MATCH(T17,CC_OP,0)), IF(AA17="FINANCIERO",OFFSET('PARÁMETROS'!$K$56,MATCH(U17,JC_FI,0),MATCH(T17,CC_FI,0)), OFFSET('PARÁMETROS'!$K$38,MATCH(U17,JC_L,0),MATCH(T17,CC_L,0))))))))),"") -> Control/Acción Eficaz | Z17: OK | AA17: =E9 -> Seguridad
P18: Capacitación/Entrenamiento | Q18: Difundir Hoja ZAP SI-164 "Importancia de la Inspección del Arnés y Conectores" | R18: Planillas de vigencia de Certificaciones / Competencias/ Capacitaciones | S18: Seguimiento al programa de reuniones y evaluaciones de compromiso con la seguridad | T18: A. Mayor 80% | U18: 2. Administrativo/ Procedimientos/ Capacitación | V18: =IFERROR(IF(AA18="SEGURIDAD",OFFSET('PARÁMETROS'!$K$2,MATCH(U18,JC_SE,0),MATCH(T18,CC_SE,0)), IF(OR(AA18="DSRC/Estratégico",AA18="DSRC/Operativo"),OFFSET('PARÁMETROS'!$K$11,MATCH(U18,JC_DS,0),MATCH(T18,CC_DS,0)), IF(AA18="SALUD",OFFSET('PARÁMETROS'!$K$29,MATCH(U18,JC_SA,0),MATCH(T18,CC_SA,0)), IF(AA18="MEDIO AMBIENTE",OFFSET('PARÁMETROS'!$K$20,MATCH(U18,JC_MA,0),MATCH(T18,CC_MA,0)), IF(AA18="Rel. Gubernamentales",OFFSET('PARÁMETROS'!$K$48,MATCH(U18,JC_G,0),MATCH(T18,CC_G,0)), IF(AA18="OPERACIONAL",OFFSET('PARÁMETROS'!$K$56,MATCH(U18,JC_OP,0),MATCH(T18,CC_OP,0)), IF(AA18="FINANCIERO",OFFSET('PARÁMETROS'!$K$56,MATCH(U18,JC_FI,0),MATCH(T18,CC_FI,0)), OFFSET('PARÁMETROS'!$K$38,MATCH(U18,JC_L,0),MATCH(T18,CC_L,0))))))))),"") -> Control/Acción Eficaz | Z18: OK | AA18: =E9 -> Seguridad
P19: Capacitación/Entrenamiento | Q19: Difundir Hoja ZAP SI-107 "Uso correcto de la Cola de Vida durante los Trabajos en Altura" | R19: Planillas de vigencia de Certificaciones / Competencias/ Capacitaciones | S19: Seguimiento al programa de reuniones y evaluaciones de compromiso con la seguridad | T19: A. Mayor 80% | U19: 2. Administrativo/ Procedimientos/ Capacitación | V19: =IFERROR(IF(AA19="SEGURIDAD",OFFSET('PARÁMETROS'!$K$2,MATCH(U19,JC_SE,0),MATCH(T19,CC_SE,0)), IF(OR(AA19="DSRC/Estratégico",AA19="DSRC/Operativo"),OFFSET('PARÁMETROS'!$K$11,MATCH(U19,JC_DS,0),MATCH(T19,CC_DS,0)), IF(AA19="SALUD",OFFSET('PARÁMETROS'!$K$29,MATCH(U19,JC_SA,0),MATCH(T19,CC_SA,0)), IF(AA19="MEDIO AMBIENTE",OFFSET('PARÁMETROS'!$K$20,MATCH(U19,JC_MA,0),MATCH(T19,CC_MA,0)), IF(AA19="Rel. Gubernamentales",OFFSET('PARÁMETROS'!$K$48,MATCH(U19,JC_G,0),MATCH(T19,CC_G,0)), IF(AA19="OPERACIONAL",OFFSET('PARÁMETROS'!$K$56,MATCH(U19,JC_OP,0),MATCH(T19,CC_OP,0)), IF(AA19="FINANCIERO",OFFSET('PARÁMETROS'!$K$56,MATCH(U19,JC_FI,0),MATCH(T19,CC_FI,0)), OFFSET('PARÁMETROS'!$K$38,MATCH(U19,JC_L,0),MATCH(T19,CC_L,0))))))))),"") -> Control/Acción Eficaz | Z19: OK | AA19: =E9 -> Seguridad
P20: E.P.P. | Q20: Usar Sistema de Protección Contra Caídas (Arnés, Conector con absorbedor de energía, conector de restricción, posicionamiento y autoretractiles) | R20: Planes / Programas | S20: Seguimiento al programa de inspecciones IRO´S: Trabajo en Altura | T20: B. 50% y 80% | U20: 1. EPP | V20: =IFERROR(IF(AA20="SEGURIDAD",OFFSET('PARÁMETROS'!$K$2,MATCH(U20,JC_SE,0),MATCH(T20,CC_SE,0)), IF(OR(AA20="DSRC/Estratégico",AA20="DSRC/Operativo"),OFFSET('PARÁMETROS'!$K$11,MATCH(U20,JC_DS,0),MATCH(T20,CC_DS,0)), IF(AA20="SALUD",OFFSET('PARÁMETROS'!$K$29,MATCH(U20,JC_SA,0),MATCH(T20,CC_SA,0)), IF(AA20="MEDIO AMBIENTE",OFFSET('PARÁMETROS'!$K$20,MATCH(U20,JC_MA,0),MATCH(T20,CC_MA,0)), IF(AA20="Rel. Gubernamentales",OFFSET('PARÁMETROS'!$K$48,MATCH(U20,JC_G,0),MATCH(T20,CC_G,0)), IF(AA20="OPERACIONAL",OFFSET('PARÁMETROS'!$K$56,MATCH(U20,JC_OP,0),MATCH(T20,CC_OP,0)), IF(AA20="FINANCIERO",OFFSET('PARÁMETROS'!$K$56,MATCH(U20,JC_FI,0),MATCH(T20,CC_FI,0)), OFFSET('PARÁMETROS'!$K$38,MATCH(U20,JC_L,0),MATCH(T20,CC_L,0))))))))),"") -> Control/Acción No Eficaz | Z20: OK | AA20: =E9 -> Seguridad
P21: Capacitación/Entrenamiento | Q21: Contar con el curso de Inducción General OHS (2.04.P05.E20 Inducción Plan de Emergencia ) | R21: Planillas de vigencia de Certificaciones / Competencias/ Capacitaciones | S21: Seguimiento a la Planilla de vigencia de cursos, autorizaciones, competencias y/o certificaciones de personas y equipos | T21: A. Mayor 80% | U21: 2. Administrativo/ Procedimientos/ Capacitación | V21: =IFERROR(IF(AA21="SEGURIDAD",OFFSET('PARÁMETROS'!$K$2,MATCH(U21,JC_SE,0),MATCH(T21,CC_SE,0)), IF(OR(AA21="DSRC/Estratégico",AA21="DSRC/Operativo"),OFFSET('PARÁMETROS'!$K$11,MATCH(U21,JC_DS,0),MATCH(T21,CC_DS,0)), IF(AA21="SALUD",OFFSET('PARÁMETROS'!$K$29,MATCH(U21,JC_SA,0),MATCH(T21,CC_SA,0)), IF(AA21="MEDIO AMBIENTE",OFFSET('PARÁMETROS'!$K$20,MATCH(U21,JC_MA,0),MATCH(T21,CC_MA,0)), IF(AA21="Rel. Gubernamentales",OFFSET('PARÁMETROS'!$K$48,MATCH(U21,JC_G,0),MATCH(T21,CC_G,0)), IF(AA21="OPERACIONAL",OFFSET('PARÁMETROS'!$K$56,MATCH(U21,JC_OP,0),MATCH(T21,CC_OP,0)), IF(AA21="FINANCIERO",OFFSET('PARÁMETROS'!$K$56,MATCH(U21,JC_FI,0),MATCH(T21,CC_FI,0)), OFFSET('PARÁMETROS'!$K$38,MATCH(U21,JC_L,0),MATCH(T21,CC_L,0))))))))),"") -> Control/Acción Eficaz | Z21: OK | AA21: =E9 -> Seguridad
P22: Controles de Salud Ocupacional | Q22: Realizar la evaluación de Salud Ocupacional al personal. | R22: Planes / Programas | S22: Seguimiento a los programas preventivos y de control en salud | T22: B. 50% y 80% | U22: 2. Administrativo/ Procedimientos/ Capacitación | V22: =IFERROR(IF(AA22="SEGURIDAD",OFFSET('PARÁMETROS'!$K$2,MATCH(U22,JC_SE,0),MATCH(T22,CC_SE,0)), IF(OR(AA22="DSRC/Estratégico",AA22="DSRC/Operativo"),OFFSET('PARÁMETROS'!$K$11,MATCH(U22,JC_DS,0),MATCH(T22,CC_DS,0)), IF(AA22="SALUD",OFFSET('PARÁMETROS'!$K$29,MATCH(U22,JC_SA,0),MATCH(T22,CC_SA,0)), IF(AA22="MEDIO AMBIENTE",OFFSET('PARÁMETROS'!$K$20,MATCH(U22,JC_MA,0),MATCH(T22,CC_MA,0)), IF(AA22="Rel. Gubernamentales",OFFSET('PARÁMETROS'!$K$48,MATCH(U22,JC_G,0),MATCH(T22,CC_G,0)), IF(AA22="OPERACIONAL",OFFSET('PARÁMETROS'!$K$56,MATCH(U22,JC_OP,0),MATCH(T22,CC_OP,0)), IF(AA22="FINANCIERO",OFFSET('PARÁMETROS'!$K$56,MATCH(U22,JC_FI,0),MATCH(T22,CC_FI,0)), OFFSET('PARÁMETROS'!$K$38,MATCH(U22,JC_L,0),MATCH(T22,CC_L,0))))))))),"") -> Control/Acción Satisfactorio | Z22: OK | AA22: =E9 -> Seguridad
P23: Inspecciones | Q23: Inspección de arnés y conectores de acuerdo a formulario 1.02.P06.F19 | R23: Planes / Programas | S23: Seguimiento al programa de inspecciones IRO´S: Trabajo en Altura | T23: B. 50% y 80% | U23: 2. Administrativo/ Procedimientos/ Capacitación | V23: =IFERROR(IF(AA23="SEGURIDAD",OFFSET('PARÁMETROS'!$K$2,MATCH(U23,JC_SE,0),MATCH(T23,CC_SE,0)), IF(OR(AA23="DSRC/Estratégico",AA23="DSRC/Operativo"),OFFSET('PARÁMETROS'!$K$11,MATCH(U23,JC_DS,0),MATCH(T23,CC_DS,0)), IF(AA23="SALUD",OFFSET('PARÁMETROS'!$K$29,MATCH(U23,JC_SA,0),MATCH(T23,CC_SA,0)), IF(AA23="MEDIO AMBIENTE",OFFSET('PARÁMETROS'!$K$20,MATCH(U23,JC_MA,0),MATCH(T23,CC_MA,0)), IF(AA23="Rel. Gubernamentales",OFFSET('PARÁMETROS'!$K$48,MATCH(U23,JC_G,0),MATCH(T23,CC_G,0)), IF(AA23="OPERACIONAL",OFFSET('PARÁMETROS'!$K$56,MATCH(U23,JC_OP,0),MATCH(T23,CC_OP,0)), IF(AA23="FINANCIERO",OFFSET('PARÁMETROS'!$K$56,MATCH(U23,JC_FI,0),MATCH(T23,CC_FI,0)), OFFSET('PARÁMETROS'!$K$38,MATCH(U23,JC_L,0),MATCH(T23,CC_L,0))))))))),"") -> Control/Acción Satisfactorio | Z23: OK | AA23: =E9 -> Seguridad
P24: E.P.P. | Q24: Usar Sistema de Protección Contra Caídas (Arnés, Conector con absorbedor de energía, conector de restricción, posicionamiento y autoretractiles) | R24: Planes / Programas | S24: Seguimiento al programa de inspecciones IRO´S: Trabajo en Altura | T24: A. Mayor 80% | U24: 1. EPP | V24: =IFERROR(IF(AA24="SEGURIDAD",OFFSET('PARÁMETROS'!$K$2,MATCH(U24,JC_SE,0),MATCH(T24,CC_SE,0)), IF(OR(AA24="DSRC/Estratégico",AA24="DSRC/Operativo"),OFFSET('PARÁMETROS'!$K$11,MATCH(U24,JC_DS,0),MATCH(T24,CC_DS,0)), IF(AA24="SALUD",OFFSET('PARÁMETROS'!$K$29,MATCH(U24,JC_SA,0),MATCH(T24,CC_SA,0)), IF(AA24="MEDIO AMBIENTE",OFFSET('PARÁMETROS'!$K$20,MATCH(U24,JC_MA,0),MATCH(T24,CC_MA,0)), IF(AA24="Rel. Gubernamentales",OFFSET('PARÁMETROS'!$K$48,MATCH(U24,JC_G,0),MATCH(T24,CC_G,0)), IF(AA24="OPERACIONAL",OFFSET('PARÁMETROS'!$K$56,MATCH(U24,JC_OP,0),MATCH(T24,CC_OP,0)), IF(AA24="FINANCIERO",OFFSET('PARÁMETROS'!$K$56,MATCH(U24,JC_FI,0),MATCH(T24,CC_FI,0)), OFFSET('PARÁMETROS'!$K$38,MATCH(U24,JC_L,0),MATCH(T24,CC_L,0))))))))),"") -> Control/Acción Satisfactorio | Z24: OK | AA24: =E9 -> Seguridad
P25: Señales/ Advertencias/ Alarmas | Q25: Señalizar Áreas de trabajo, almacenaje de materiales y pasillos de circulación | R25: Publicación de Indicadores | S25: Seguimiento y publicación de reporte STOP o Seguimiento y publicación de reporte de observaciones conductuales | T25: A. Mayor 80% | U25: 3. Señalización/ Advertencias/ Alarma | V25: =IFERROR(IF(AA25="SEGURIDAD",OFFSET('PARÁMETROS'!$K$2,MATCH(U25,JC_SE,0),MATCH(T25,CC_SE,0)), IF(OR(AA25="DSRC/Estratégico",AA25="DSRC/Operativo"),OFFSET('PARÁMETROS'!$K$11,MATCH(U25,JC_DS,0),MATCH(T25,CC_DS,0)), IF(AA25="SALUD",OFFSET('PARÁMETROS'!$K$29,MATCH(U25,JC_SA,0),MATCH(T25,CC_SA,0)), IF(AA25="MEDIO AMBIENTE",OFFSET('PARÁMETROS'!$K$20,MATCH(U25,JC_MA,0),MATCH(T25,CC_MA,0)), IF(AA25="Rel. Gubernamentales",OFFSET('PARÁMETROS'!$K$48,MATCH(U25,JC_G,0),MATCH(T25,CC_G,0)), IF(AA25="OPERACIONAL",OFFSET('PARÁMETROS'!$K$56,MATCH(U25,JC_OP,0),MATCH(T25,CC_OP,0)), IF(AA25="FINANCIERO",OFFSET('PARÁMETROS'!$K$56,MATCH(U25,JC_FI,0),MATCH(T25,CC_FI,0)), OFFSET('PARÁMETROS'!$K$38,MATCH(U25,JC_L,0),MATCH(T25,CC_L,0))))))))),"") -> Control/Acción Eficaz | Z25: OK | AA25: =E9 -> Seguridad
P26: Procedimientos / Instructivos / Reglamentos y otros. | Q26: Implementar formularios ART/VPT según Guía para la Identificación y Evaluación de Riesgos 1.02.P06.I01 para realizar trabajo de Desmontaje y montaje de componentes del Chancador Primario (araña, cóncavos, eje principal) | R26: Planes / Programas | S26: Seguimiento al programa de inspecciones IRO´S: Trabajo en Altura | T26: B. 50% y 80% | U26: 2. Administrativo/ Procedimientos/ Capacitación | V26: =IFERROR(IF(AA26="SEGURIDAD",OFFSET('PARÁMETROS'!$K$2,MATCH(U26,JC_SE,0),MATCH(T26,CC_SE,0)), IF(OR(AA26="DSRC/Estratégico",AA26="DSRC/Operativo"),OFFSET('PARÁMETROS'!$K$11,MATCH(U26,JC_DS,0),MATCH(T26,CC_DS,0)), IF(AA26="SALUD",OFFSET('PARÁMETROS'!$K$29,MATCH(U26,JC_SA,0),MATCH(T26,CC_SA,0)), IF(AA26="MEDIO AMBIENTE",OFFSET('PARÁMETROS'!$K$20,MATCH(U26,JC_MA,0),MATCH(T26,CC_MA,0)), IF(AA26="Rel. Gubernamentales",OFFSET('PARÁMETROS'!$K$48,MATCH(U26,JC_G,0),MATCH(T26,CC_G,0)), IF(AA26="OPERACIONAL",OFFSET('PARÁMETROS'!$K$56,MATCH(U26,JC_OP,0),MATCH(T26,CC_OP,0)), IF(AA26="FINANCIERO",OFFSET('PARÁMETROS'!$K$56,MATCH(U26,JC_FI,0),MATCH(T26,CC_FI,0)), OFFSET('PARÁMETROS'!$K$38,MATCH(U26,JC_L,0),MATCH(T26,CC_L,0))))))))),"") -> Control/Acción Satisfactorio | Z26: Además de la documentación que se señala (ART/VPT), debe incluirse la obligatoriedad a contar con PT para Trabajo en Altura vigente | AA26: SE ADICIONA EL CUMPLIMIENTO AL INSTRUCTIVO DE ALTURA
A27: 3 | B27: Mantenimiento Chancador | C27: Desmontaje y montaje de componentes del Chancador Primario (araña, cóncavos, eje principal) | D27: Normal | E27: Seguridad | F27: Energía almacenada que puede liberarse repentinamente | G27: Falta de aislamiento o aislamiento incompleto de equipos de procesos a sufrir mantenimiento | H27: Liberación de energía peligrosa (hidráulica, neumática, eléctrica, radioactiva, etc.) | I27: Contacto con energía peligrosa, presión de agua, presión de aire, energía térmica, energía eléctrica | J27: 2 | K27: 2 | L27: =IF(OR(J27<>"",K27<>""),OFFSET('PARÁMETROS'!$B$2,K27,J27),"") -> 5 | M27: 5 | N27: =IFERROR(L27*M27,"") -> 25 | O27: =IF(N27="","",IFERROR(IF(N27<=2,"ACEPTABLE",IF(N27<=6,"BAJA",IF(N27<=10,"ACEPTABLE CON REVISIÓN",IF(N27<=15,"SUSTANCIAL","INACEPTABLE")))),"")) -> INACEPTABLE | P27: Capacitación/Entrenamiento | Q27: Capacitar al personal sobre los estándares del Instructivo de Aislamiento de equipos 1.02.P06.I24 | R27: Planes / Programas | S27: Seguimiento al programa de difusión de instructivos y capacitaciones internas | T27: C. Menor a 50% | U27: 2. Administrativo/ Procedimientos/ Capacitación | V27: =IFERROR(IF(AA27="SEGURIDAD",OFFSET('PARÁMETROS'!$K$2,MATCH(U27,JC_SE,0),MATCH(T27,CC_SE,0)), IF(OR(AA27="DSRC/Estratégico",AA27="DSRC/Operativo"),OFFSET('PARÁMETROS'!$K$11,MATCH(U27,JC_DS,0),MATCH(T27,CC_DS,0)), IF(AA27="SALUD",OFFSET('PARÁMETROS'!$K$29,MATCH(U27,JC_SA,0),MATCH(T27,CC_SA,0)), IF(AA27="MEDIO AMBIENTE",OFFSET('PARÁMETROS'!$K$20,MATCH(U27,JC_MA,0),MATCH(T27,CC_MA,0)), IF(AA27="Rel. Gubernamentales",OFFSET('PARÁMETROS'!$K$48,MATCH(U27,JC_G,0),MATCH(T27,CC_G,0)), IF(AA27="OPERACIONAL",OFFSET('PARÁMETROS'!$K$56,MATCH(U27,JC_OP,0),MATCH(T27,CC_OP,0)), IF(AA27="FINANCIERO",OFFSET('PARÁMETROS'!$K$56,MATCH(U27,JC_FI,0),MATCH(T27,CC_FI,0)), OFFSET('PARÁMETROS'!$K$38,MATCH(U27,JC_L,0),MATCH(T27,CC_L,0))))))))),"") -> Control/Acción No Eficaz | W27: =IF(E27="","", IF(COUNTA( V27:V39)-COUNTBLANK( V27:V39)=1, IF(O27="INACEPTABLE",IF(COUNTIF( V27:V39,"Control/Acción Eficaz")>=1,"SUSTANCIAL","INACEPTABLE"), IF(O27="SUSTANCIAL",IF(COUNTIF( V27:V39,"Control/Acción Eficaz")>=1,"ACEPTABLE CON REVISIÓN","SUSTANCIAL"), IF(O27="ACEPTABLE CON REVISIÓN",IF(COUNTIF( V27:V39,"Control/Acción Eficaz")>=1,"BAJA","ACEPTABLE CON REVISIÓN"), IF(O27="BAJA",IF(COUNTIF( V27:V39,"Control/Acción Eficaz")>=1,"ACEPTABLE","BAJA"),)))), IF(COUNTA( V27:V39)-COUNTBLANK( V27:V39)=2, IF(O27="INACEPTABLE",IF(COUNTIF( V27:V39,"Control/Acción Eficaz")=2,"ACEPTABLE CON REVISIÓN", IF(OR(AND(COUNTIF( V27:V39,"Control/Acción Eficaz")=1,COUNTIF( V27:V39,"Control/Acción Satisfactorio")=1), AND(COUNTIF( V27:V39,"Control/Acción Eficaz")=1,COUNTIF( V27:V39,"Control/Acción No Eficaz")=1)),"SUSTANCIAL","INACEPTABLE")), IF(O27="SUSTANCIAL",IF(COUNTIF( V27:V39,"Control/Acción Eficaz")=2,"BAJA", IF(OR(AND(COUNTIF( V27:V39,"Control/Acción Eficaz")=1,COUNTIF( V27:V39,"Control/Acción Satisfactorio")=1), AND(COUNTIF( V27:V39,"Control/Acción Eficaz")=1,COUNTIF( V27:V39,"Control/Acción No Eficaz")=1)),"ACEPTABLE CON REVISIÓN ","SUSTANCIAL")), IF(O27="ACEPTABLE CON REVISIÓN",IF(COUNTIF( V27:V39,"Control/Acción Eficaz")=2,"ACEPTABLE", IF(OR(AND(COUNTIF( V27:V39,"Control/Acción Eficaz")=1,COUNTIF( V27:V39,"Control/Acción Satisfactorio")=1), AND(COUNTIF( V27:V39,"Control/Acción Eficaz")=1,COUNTIF( V27:V39,"Control/Acción No Eficaz")=1)),"BAJA","ACEPTABLE CON REVISIÓN")), IF(O27="BAJA",IF(COUNTIF( V27:V39,"Control/Acción Eficaz")>=2,"ACEPTABLE","BAJA"),)))), IF(COUNTA( V27:V39)-COUNTBLANK( V27:V39)>=3, IF(O27="INACEPTABLE", IF(COUNTBLANK( V27:V39)=COUNTA( V27:V39),"", IF(COUNTIF( V27:V39,"Control/Acción No Eficaz")>=2,"INACEPTABLE", IF(AND(COUNTIF( V27:V39,"Control/Acción No Eficaz")=0,COUNTIF( V27:V39,"Control/Acción Eficaz")>=2),"ACEPTABLE CON REVISIÓN ","SUSTANCIAL"))), IF(O27="SUSTANCIAL", IF(COUNTBLANK( V27:V39)=COUNTA( V27:V39),"", IF(COUNTIF( V27:V39,"Control/Acción No Eficaz")>=2,"SUSTANCIAL", IF(AND(COUNTIF( V27:V39,"Control/Acción No Eficaz")=0,COUNTIF( V27:V39,"Control/Acción Eficaz")>=2),"BAJA","ACEPTABLE CON REVISIÓN"))), IF(O27="ACEPTABLE CON REVISIÓN", IF(COUNTBLANK( V27:V39)=COUNTA( V27:V39),"", IF(COUNTIF( V27:V39,"Control/Acción No Eficaz")>=2,"ACEPTABLE CON REVISIÓN", IF(AND(COUNTIF( V27:V39,"Control/Acción No Eficaz")=0,COUNTIF( V27:V39,"Control/Acción Eficaz")>=2),"ACEPTABLE","BAJA"))), IF(O27="BAJA", IF(COUNTBLANK( V27:V39)=COUNTA( V27:V39),"", IF(AND(COUNTBLANK( V27:V39)<1,COUNTA( V27:V39)=1), IF(COUNTIF( V27:V39,"Control/Acción No Eficaz")>=2,"BAJA", IF(AND(COUNTIF( V27:V39,"Control/Acción No Eficaz")=0,COUNTIF( V27:V39,"Control/Acción Eficaz")>=2),"ACEPTABLE","BAJA")), IF(COUNTIF( V27:V39,"Control/Acción No Eficaz")>=2,"BAJA", IF(AND(COUNTIF( V27:V39,"Control/Acción No Eficaz")=0,COUNTIF( V27:V39,"Control/Acción Eficaz")>=2),"ACEPTABLE","BAJA")))), IF(COUNTIF( V27:V39,"")>=5,"",O27))))), "")))) -> INACEPTABLE | Z27: OK | AA27: =E27 -> Seguridad
P28: Competencias | Q28: Contar con personal competente en Control de Energías (Bloqueo y Etiquetado) | R28: Planillas de vigencia de Certificaciones / Competencias/ Capacitaciones | S28: Seguimiento a la Planilla de vigencia de cursos, autorizaciones, competencias y/o certificaciones de personas y equipos | T28: A. Mayor 80% | U28: 2. Administrativo/ Procedimientos/ Capacitación | V28: =IFERROR(IF(AA28="SEGURIDAD",OFFSET('PARÁMETROS'!$K$2,MATCH(U28,JC_SE,0),MATCH(T28,CC_SE,0)), IF(OR(AA28="DSRC/Estratégico",AA28="DSRC/Operativo"),OFFSET('PARÁMETROS'!$K$11,MATCH(U28,JC_DS,0),MATCH(T28,CC_DS,0)), IF(AA28="SALUD",OFFSET('PARÁMETROS'!$K$29,MATCH(U28,JC_SA,0),MATCH(T28,CC_SA,0)), IF(AA28="MEDIO AMBIENTE",OFFSET('PARÁMETROS'!$K$20,MATCH(U28,JC_MA,0),MATCH(T28,CC_MA,0)), IF(AA28="Rel. Gubernamentales",OFFSET('PARÁMETROS'!$K$48,MATCH(U28,JC_G,0),MATCH(T28,CC_G,0)), IF(AA28="OPERACIONAL",OFFSET('PARÁMETROS'!$K$56,MATCH(U28,JC_OP,0),MATCH(T28,CC_OP,0)), IF(AA28="FINANCIERO",OFFSET('PARÁMETROS'!$K$56,MATCH(U28,JC_FI,0),MATCH(T28,CC_FI,0)), OFFSET('PARÁMETROS'!$K$38,MATCH(U28,JC_L,0),MATCH(T28,CC_L,0))))))))),"") -> Control/Acción Eficaz | Z28: OK | AA28: =E27 -> Seguridad
P29: Capacitación/Entrenamiento | Q29: Capacitar al personal sobre los estándares del Instructivo de Aislamiento de equipos 1.02.P06.I24 | R29: Planes / Programas | S29: Seguimiento al programa de difusión de instructivos y capacitaciones internas | T29: B. 50% y 80% | U29: 2. Administrativo/ Procedimientos/ Capacitación | V29: =IFERROR(IF(AA29="SEGURIDAD",OFFSET('PARÁMETROS'!$K$2,MATCH(U29,JC_SE,0),MATCH(T29,CC_SE,0)), IF(OR(AA29="DSRC/Estratégico",AA29="DSRC/Operativo"),OFFSET('PARÁMETROS'!$K$11,MATCH(U29,JC_DS,0),MATCH(T29,CC_DS,0)), IF(AA29="SALUD",OFFSET('PARÁMETROS'!$K$29,MATCH(U29,JC_SA,0),MATCH(T29,CC_SA,0)), IF(AA29="MEDIO AMBIENTE",OFFSET('PARÁMETROS'!$K$20,MATCH(U29,JC_MA,0),MATCH(T29,CC_MA,0)), IF(AA29="Rel. Gubernamentales",OFFSET('PARÁMETROS'!$K$48,MATCH(U29,JC_G,0),MATCH(T29,CC_G,0)), IF(AA29="OPERACIONAL",OFFSET('PARÁMETROS'!$K$56,MATCH(U29,JC_OP,0),MATCH(T29,CC_OP,0)), IF(AA29="FINANCIERO",OFFSET('PARÁMETROS'!$K$56,MATCH(U29,JC_FI,0),MATCH(T29,CC_FI,0)), OFFSET('PARÁMETROS'!$K$38,MATCH(U29,JC_L,0),MATCH(T29,CC_L,0))))))))),"") -> Control/Acción Satisfactorio | Z29: OK | AA29: =E27 -> Seguridad
P30: Señales/ Advertencias/ Alarmas | Q30: Señalizar área de trabajo al realizar el control de energía | R30: Publicación de Indicadores | S30: Seguimiento y publicación de reporte STOP o Seguimiento y publicación de reporte de observaciones conductuales | T30: B. 50% y 80% | U30: 3. Señalización/ Advertencias/ Alarma | V30: =IFERROR(IF(AA30="SEGURIDAD",OFFSET('PARÁMETROS'!$K$2,MATCH(U30,JC_SE,0),MATCH(T30,CC_SE,0)), IF(OR(AA30="DSRC/Estratégico",AA30="DSRC/Operativo"),OFFSET('PARÁMETROS'!$K$11,MATCH(U30,JC_DS,0),MATCH(T30,CC_DS,0)), IF(AA30="SALUD",OFFSET('PARÁMETROS'!$K$29,MATCH(U30,JC_SA,0),MATCH(T30,CC_SA,0)), IF(AA30="MEDIO AMBIENTE",OFFSET('PARÁMETROS'!$K$20,MATCH(U30,JC_MA,0),MATCH(T30,CC_MA,0)), IF(AA30="Rel. Gubernamentales",OFFSET('PARÁMETROS'!$K$48,MATCH(U30,JC_G,0),MATCH(T30,CC_G,0)), IF(AA30="OPERACIONAL",OFFSET('PARÁMETROS'!$K$56,MATCH(U30,JC_OP,0),MATCH(T30,CC_OP,0)), IF(AA30="FINANCIERO",OFFSET('PARÁMETROS'!$K$56,MATCH(U30,JC_FI,0),MATCH(T30,CC_FI,0)), OFFSET('PARÁMETROS'!$K$38,MATCH(U30,JC_L,0),MATCH(T30,CC_L,0))))))))),"") -> Control/Acción Satisfactorio | Z30: OK | AA30: =E27 -> Seguridad
P31: Capacitación/Entrenamiento | Q31: Contar con el curso de Inducción General OHS (2.04.P05.E20 Inducción Plan de Emergencia ) | R31: Planillas de vigencia de Certificaciones / Competencias/ Capacitaciones | S31: Seguimiento a la Planilla de vigencia de cursos, autorizaciones, competencias y/o certificaciones de personas y equipos | T31: A. Mayor 80% | U31: 2. Administrativo/ Procedimientos/ Capacitación | V31: =IFERROR(IF(AA31="SEGURIDAD",OFFSET('PARÁMETROS'!$K$2,MATCH(U31,JC_SE,0),MATCH(T31,CC_SE,0)), IF(OR(AA31="DSRC/Estratégico",AA31="DSRC/Operativo"),OFFSET('PARÁMETROS'!$K$11,MATCH(U31,JC_DS,0),MATCH(T31,CC_DS,0)), IF(AA31="SALUD",OFFSET('PARÁMETROS'!$K$29,MATCH(U31,JC_SA,0),MATCH(T31,CC_SA,0)), IF(AA31="MEDIO AMBIENTE",OFFSET('PARÁMETROS'!$K$20,MATCH(U31,JC_MA,0),MATCH(T31,CC_MA,0)), IF(AA31="Rel. Gubernamentales",OFFSET('PARÁMETROS'!$K$48,MATCH(U31,JC_G,0),MATCH(T31,CC_G,0)), IF(AA31="OPERACIONAL",OFFSET('PARÁMETROS'!$K$56,MATCH(U31,JC_OP,0),MATCH(T31,CC_OP,0)), IF(AA31="FINANCIERO",OFFSET('PARÁMETROS'!$K$56,MATCH(U31,JC_FI,0),MATCH(T31,CC_FI,0)), OFFSET('PARÁMETROS'!$K$38,MATCH(U31,JC_L,0),MATCH(T31,CC_L,0))))))))),"") -> Control/Acción Eficaz | Z31: OK | AA31: =E27 -> Seguridad
P32: Capacitación/Entrenamiento | Q32: Capacitar al personal sobre respuesta ante emergencias descrito del Plan de Emergencia 2.04.P05.E20 | R32: Planes / Programas | S32: Seguimiento al programa de difusión de instructivos y capacitaciones internas | T32: B. 50% y 80% | U32: 2. Administrativo/ Procedimientos/ Capacitación | V32: =IFERROR(IF(AA32="SEGURIDAD",OFFSET('PARÁMETROS'!$K$2,MATCH(U32,JC_SE,0),MATCH(T32,CC_SE,0)), IF(OR(AA32="DSRC/Estratégico",AA32="DSRC/Operativo"),OFFSET('PARÁMETROS'!$K$11,MATCH(U32,JC_DS,0),MATCH(T32,CC_DS,0)), IF(AA32="SALUD",OFFSET('PARÁMETROS'!$K$29,MATCH(U32,JC_SA,0),MATCH(T32,CC_SA,0)), IF(AA32="MEDIO AMBIENTE",OFFSET('PARÁMETROS'!$K$20,MATCH(U32,JC_MA,0),MATCH(T32,CC_MA,0)), IF(AA32="Rel. Gubernamentales",OFFSET('PARÁMETROS'!$K$48,MATCH(U32,JC_G,0),MATCH(T32,CC_G,0)), IF(AA32="OPERACIONAL",OFFSET('PARÁMETROS'!$K$56,MATCH(U32,JC_OP,0),MATCH(T32,CC_OP,0)), IF(AA32="FINANCIERO",OFFSET('PARÁMETROS'!$K$56,MATCH(U32,JC_FI,0),MATCH(T32,CC_FI,0)), OFFSET('PARÁMETROS'!$K$38,MATCH(U32,JC_L,0),MATCH(T32,CC_L,0))))))))),"") -> Control/Acción Satisfactorio | Z32: OK | AA32: =E27 -> Seguridad
P33: Controles/Acciones de Emergencias | Q33: Difundir la ruta de evacuación para caso de emergencia, punto de reunión y protocolo de emergencia | R33: Planes / Programas | S33: Seguimiento al programa de reuniones y evaluaciones de compromiso con la seguridad | T33: B. 50% y 80% | U33: 2. Administrativo/ Procedimientos/ Capacitación | V33: =IFERROR(IF(AA33="SEGURIDAD",OFFSET('PARÁMETROS'!$K$2,MATCH(U33,JC_SE,0),MATCH(T33,CC_SE,0)), IF(OR(AA33="DSRC/Estratégico",AA33="DSRC/Operativo"),OFFSET('PARÁMETROS'!$K$11,MATCH(U33,JC_DS,0),MATCH(T33,CC_DS,0)), IF(AA33="SALUD",OFFSET('PARÁMETROS'!$K$29,MATCH(U33,JC_SA,0),MATCH(T33,CC_SA,0)), IF(AA33="MEDIO AMBIENTE",OFFSET('PARÁMETROS'!$K$20,MATCH(U33,JC_MA,0),MATCH(T33,CC_MA,0)), IF(AA33="Rel. Gubernamentales",OFFSET('PARÁMETROS'!$K$48,MATCH(U33,JC_G,0),MATCH(T33,CC_G,0)), IF(AA33="OPERACIONAL",OFFSET('PARÁMETROS'!$K$56,MATCH(U33,JC_OP,0),MATCH(T33,CC_OP,0)), IF(AA33="FINANCIERO",OFFSET('PARÁMETROS'!$K$56,MATCH(U33,JC_FI,0),MATCH(T33,CC_FI,0)), OFFSET('PARÁMETROS'!$K$38,MATCH(U33,JC_L,0),MATCH(T33,CC_L,0))))))))),"") -> Control/Acción Satisfactorio | Z33: OK | AA33: =E27 -> Seguridad
P34: E.P.P. | Q34: Usar EPP básico y adicional (Casco, botines de Seguridad, Lentes), guantes y carrilera de casco | R34: Publicación de Indicadores | S34: Seguimiento y publicación de reporte STOP o Seguimiento y publicación de reporte de observaciones conductuales | T34: B. 50% y 80% | U34: 1. EPP | V34: =IFERROR(IF(AA34="SEGURIDAD",OFFSET('PARÁMETROS'!$K$2,MATCH(U34,JC_SE,0),MATCH(T34,CC_SE,0)), IF(OR(AA34="DSRC/Estratégico",AA34="DSRC/Operativo"),OFFSET('PARÁMETROS'!$K$11,MATCH(U34,JC_DS,0),MATCH(T34,CC_DS,0)), IF(AA34="SALUD",OFFSET('PARÁMETROS'!$K$29,MATCH(U34,JC_SA,0),MATCH(T34,CC_SA,0)), IF(AA34="MEDIO AMBIENTE",OFFSET('PARÁMETROS'!$K$20,MATCH(U34,JC_MA,0),MATCH(T34,CC_MA,0)), IF(AA34="Rel. Gubernamentales",OFFSET('PARÁMETROS'!$K$48,MATCH(U34,JC_G,0),MATCH(T34,CC_G,0)), IF(AA34="OPERACIONAL",OFFSET('PARÁMETROS'!$K$56,MATCH(U34,JC_OP,0),MATCH(T34,CC_OP,0)), IF(AA34="FINANCIERO",OFFSET('PARÁMETROS'!$K$56,MATCH(U34,JC_FI,0),MATCH(T34,CC_FI,0)), OFFSET('PARÁMETROS'!$K$38,MATCH(U34,JC_L,0),MATCH(T34,CC_L,0))))))))),"") -> Control/Acción No Eficaz | Z34: OK | AA34: =E27 -> Seguridad
P35: Capacitación/Entrenamiento | Q35: Difundir Hoja ZAP SI-050 "Pasos para aislamiento con candados personales" | R35: Planillas de vigencia de Certificaciones / Competencias/ Capacitaciones | S35: Seguimiento al programa de reuniones y evaluaciones de compromiso con la seguridad | T35: A. Mayor 80% | U35: 2. Administrativo/ Procedimientos/ Capacitación | V35: =IFERROR(IF(AA35="SEGURIDAD",OFFSET('PARÁMETROS'!$K$2,MATCH(U35,JC_SE,0),MATCH(T35,CC_SE,0)), IF(OR(AA35="DSRC/Estratégico",AA35="DSRC/Operativo"),OFFSET('PARÁMETROS'!$K$11,MATCH(U35,JC_DS,0),MATCH(T35,CC_DS,0)), IF(AA35="SALUD",OFFSET('PARÁMETROS'!$K$29,MATCH(U35,JC_SA,0),MATCH(T35,CC_SA,0)), IF(AA35="MEDIO AMBIENTE",OFFSET('PARÁMETROS'!$K$20,MATCH(U35,JC_MA,0),MATCH(T35,CC_MA,0)), IF(AA35="Rel. Gubernamentales",OFFSET('PARÁMETROS'!$K$48,MATCH(U35,JC_G,0),MATCH(T35,CC_G,0)), IF(AA35="OPERACIONAL",OFFSET('PARÁMETROS'!$K$56,MATCH(U35,JC_OP,0),MATCH(T35,CC_OP,0)), IF(AA35="FINANCIERO",OFFSET('PARÁMETROS'!$K$56,MATCH(U35,JC_FI,0),MATCH(T35,CC_FI,0)), OFFSET('PARÁMETROS'!$K$38,MATCH(U35,JC_L,0),MATCH(T35,CC_L,0))))))))),"") -> Control/Acción Eficaz | Z35: OK | AA35: =E27 -> Seguridad
P36: Capacitación/Entrenamiento | Q36: Difundir Hoja ZAP SI-051 "Candado personal de aislamiento y tarjeta de peligro" | R36: Planillas de vigencia de Certificaciones / Competencias/ Capacitaciones | S36: Seguimiento al programa de reuniones y evaluaciones de compromiso con la seguridad | T36: A. Mayor 80% | U36: 2. Administrativo/ Procedimientos/ Capacitación | V36: =IFERROR(IF(AA36="SEGURIDAD",OFFSET('PARÁMETROS'!$K$2,MATCH(U36,JC_SE,0),MATCH(T36,CC_SE,0)), IF(OR(AA36="DSRC/Estratégico",AA36="DSRC/Operativo"),OFFSET('PARÁMETROS'!$K$11,MATCH(U36,JC_DS,0),MATCH(T36,CC_DS,0)), IF(AA36="SALUD",OFFSET('PARÁMETROS'!$K$29,MATCH(U36,JC_SA,0),MATCH(T36,CC_SA,0)), IF(AA36="MEDIO AMBIENTE",OFFSET('PARÁMETROS'!$K$20,MATCH(U36,JC_MA,0),MATCH(T36,CC_MA,0)), IF(AA36="Rel. Gubernamentales",OFFSET('PARÁMETROS'!$K$48,MATCH(U36,JC_G,0),MATCH(T36,CC_G,0)), IF(AA36="OPERACIONAL",OFFSET('PARÁMETROS'!$K$56,MATCH(U36,JC_OP,0),MATCH(T36,CC_OP,0)), IF(AA36="FINANCIERO",OFFSET('PARÁMETROS'!$K$56,MATCH(U36,JC_FI,0),MATCH(T36,CC_FI,0)), OFFSET('PARÁMETROS'!$K$38,MATCH(U36,JC_L,0),MATCH(T36,CC_L,0))))))))),"") -> Control/Acción Eficaz | Z36: OK
P37: Controles de Ingeniería | Q37: Contar con dispositivos de bloqueos físicos de energías almacenadas | R37: Publicación de Indicadores | S37: Seguimiento y publicación de reporte STOP o Seguimiento y publicación de reporte de observaciones conductuales | T37: B. 50% y 80% | U37: 4. Ingeniería | V37: =IFERROR(IF(AA37="SEGURIDAD",OFFSET('PARÁMETROS'!$K$2,MATCH(U37,JC_SE,0),MATCH(T37,CC_SE,0)), IF(OR(AA37="DSRC/Estratégico",AA37="DSRC/Operativo"),OFFSET('PARÁMETROS'!$K$11,MATCH(U37,JC_DS,0),MATCH(T37,CC_DS,0)), IF(AA37="SALUD",OFFSET('PARÁMETROS'!$K$29,MATCH(U37,JC_SA,0),MATCH(T37,CC_SA,0)), IF(AA37="MEDIO AMBIENTE",OFFSET('PARÁMETROS'!$K$20,MATCH(U37,JC_MA,0),MATCH(T37,CC_MA,0)), IF(AA37="Rel. Gubernamentales",OFFSET('PARÁMETROS'!$K$48,MATCH(U37,JC_G,0),MATCH(T37,CC_G,0)), IF(AA37="OPERACIONAL",OFFSET('PARÁMETROS'!$K$56,MATCH(U37,JC_OP,0),MATCH(T37,CC_OP,0)), IF(AA37="FINANCIERO",OFFSET('PARÁMETROS'!$K$56,MATCH(U37,JC_FI,0),MATCH(T37,CC_FI,0)), OFFSET('PARÁMETROS'!$K$38,MATCH(U37,JC_L,0),MATCH(T37,CC_L,0))))))))),"") -> Control/Acción Satisfactorio | Z37: OK | AA37: =E27 -> Seguridad
P38: Competencias | Q38: Contar con personal competente en Control de Energías (Bloqueo y Etiquetado) | R38: Planillas de vigencia de Certificaciones / Competencias/ Capacitaciones | S38: Seguimiento a la Planilla de vigencia de cursos, autorizaciones, competencias y/o certificaciones de personas y equipos | T38: A. Mayor 80% | U38: 2. Administrativo/ Procedimientos/ Capacitación | V38: =IFERROR(IF(AA38="SEGURIDAD",OFFSET('PARÁMETROS'!$K$2,MATCH(U38,JC_SE,0),MATCH(T38,CC_SE,0)), IF(OR(AA38="DSRC/Estratégico",AA38="DSRC/Operativo"),OFFSET('PARÁMETROS'!$K$11,MATCH(U38,JC_DS,0),MATCH(T38,CC_DS,0)), IF(AA38="SALUD",OFFSET('PARÁMETROS'!$K$29,MATCH(U38,JC_SA,0),MATCH(T38,CC_SA,0)), IF(AA38="MEDIO AMBIENTE",OFFSET('PARÁMETROS'!$K$20,MATCH(U38,JC_MA,0),MATCH(T38,CC_MA,0)), IF(AA38="Rel. Gubernamentales",OFFSET('PARÁMETROS'!$K$48,MATCH(U38,JC_G,0),MATCH(T38,CC_G,0)), IF(AA38="OPERACIONAL",OFFSET('PARÁMETROS'!$K$56,MATCH(U38,JC_OP,0),MATCH(T38,CC_OP,0)), IF(AA38="FINANCIERO",OFFSET('PARÁMETROS'!$K$56,MATCH(U38,JC_FI,0),MATCH(T38,CC_FI,0)), OFFSET('PARÁMETROS'!$K$38,MATCH(U38,JC_L,0),MATCH(T38,CC_L,0))))))))),"") -> Control/Acción Eficaz | Z38: OK | AA38: =E27 -> Seguridad
P39: Procedimientos / Instructivos / Reglamentos y otros. | Q39: Implementar formularios ART/VPT según Guía para la Identificación y Evaluación de Riesgos 1.02.P06.I01 para realizar trabajo de Desmontaje y montaje de componentes del Chancador Primario (araña, cóncavos, eje principal) | R39: Publicación de Indicadores | S39: Seguimiento y publicación de reporte STOP o Seguimiento y publicación de reporte de observaciones conductuales | T39: B. 50% y 80% | U39: 2. Administrativo/ Procedimientos/ Capacitación | V39: =IFERROR(IF(AA39="SEGURIDAD",OFFSET('PARÁMETROS'!$K$2,MATCH(U39,JC_SE,0),MATCH(T39,CC_SE,0)), IF(OR(AA39="DSRC/Estratégico",AA39="DSRC/Operativo"),OFFSET('PARÁMETROS'!$K$11,MATCH(U39,JC_DS,0),MATCH(T39,CC_DS,0)), IF(AA39="SALUD",OFFSET('PARÁMETROS'!$K$29,MATCH(U39,JC_SA,0),MATCH(T39,CC_SA,0)), IF(AA39="MEDIO AMBIENTE",OFFSET('PARÁMETROS'!$K$20,MATCH(U39,JC_MA,0),MATCH(T39,CC_MA,0)), IF(AA39="Rel. Gubernamentales",OFFSET('PARÁMETROS'!$K$48,MATCH(U39,JC_G,0),MATCH(T39,CC_G,0)), IF(AA39="OPERACIONAL",OFFSET('PARÁMETROS'!$K$56,MATCH(U39,JC_OP,0),MATCH(T39,CC_OP,0)), IF(AA39="FINANCIERO",OFFSET('PARÁMETROS'!$K$56,MATCH(U39,JC_FI,0),MATCH(T39,CC_FI,0)), OFFSET('PARÁMETROS'!$K$38,MATCH(U39,JC_L,0),MATCH(T39,CC_L,0))))))))),"") -> Control/Acción Satisfactorio | Z39: OK | AA39: =E27 -> Seguridad
A40: 4 | B40: Mantenimiento Chancador | C40: Desmontaje y montaje de componentes del Chancador Primario (araña, cóncavos, eje principal) | D40: Normal | E40: Seguridad | F40: Manipulación/uso de herramientas, instrumentos, objetos (cortantes, punzantes, calientes, pesados, sin Verificación / Calibración, etc.) | G40: Manipulación de herramientas manuales, herramientas defectuosas o inadecuadas (combos, llaves, palas) | H40: Golpeado por | I40: Golpes en las manos y pies por uso de herramienta defectuosa, zafe de llaves, u otros | J40: 3 | K40: 3 | L40: =IF(OR(J40<>"",K40<>""),OFFSET('PARÁMETROS'!$B$2,K40,J40),"") -> 4 | M40: 3 | N40: =IFERROR(L40*M40,"") -> 12 | O40: =IF(N40="","",IFERROR(IF(N40<=2,"ACEPTABLE",IF(N40<=6,"BAJA",IF(N40<=10,"ACEPTABLE CON REVISIÓN",IF(N40<=15,"SUSTANCIAL","INACEPTABLE")))),"")) -> SUSTANCIAL | P40: Capacitación/Entrenamiento | Q40: Capacitar al personal los estándares del Instructivo de Manipulación Manual de Cargas 1.02.P06.I14 | R40: Planes / Programas | S40: Seguimiento al programa de difusión de instructivos y capacitaciones internas | T40: B. 50% y 80% | U40: 2. Administrativo/ Procedimientos/ Capacitación | V40: =IFERROR(IF(AA40="SEGURIDAD",OFFSET('PARÁMETROS'!$K$2,MATCH(U40,JC_SE,0),MATCH(T40,CC_SE,0)), IF(OR(AA40="DSRC/Estratégico",AA40="DSRC/Operativo"),OFFSET('PARÁMETROS'!$K$11,MATCH(U40,JC_DS,0),MATCH(T40,CC_DS,0)), IF(AA40="SALUD",OFFSET('PARÁMETROS'!$K$29,MATCH(U40,JC_SA,0),MATCH(T40,CC_SA,0)), IF(AA40="MEDIO AMBIENTE",OFFSET('PARÁMETROS'!$K$20,MATCH(U40,JC_MA,0),MATCH(T40,CC_MA,0)), IF(AA40="Rel. Gubernamentales",OFFSET('PARÁMETROS'!$K$48,MATCH(U40,JC_G,0),MATCH(T40,CC_G,0)), IF(AA40="OPERACIONAL",OFFSET('PARÁMETROS'!$K$56,MATCH(U40,JC_OP,0),MATCH(T40,CC_OP,0)), IF(AA40="FINANCIERO",OFFSET('PARÁMETROS'!$K$56,MATCH(U40,JC_FI,0),MATCH(T40,CC_FI,0)), OFFSET('PARÁMETROS'!$K$38,MATCH(U40,JC_L,0),MATCH(T40,CC_L,0))))))))),"") -> Control/Acción Satisfactorio | W40: =IF(E40="","", IF(COUNTA( V40:V50)-COUNTBLANK( V40:V50)=1, IF(O40="INACEPTABLE",IF(COUNTIF( V40:V50,"Control/Acción Eficaz")>=1,"SUSTANCIAL","INACEPTABLE"), IF(O40="SUSTANCIAL",IF(COUNTIF( V40:V50,"Control/Acción Eficaz")>=1,"ACEPTABLE CON REVISIÓN","SUSTANCIAL"), IF(O40="ACEPTABLE CON REVISIÓN",IF(COUNTIF( V40:V50,"Control/Acción Eficaz")>=1,"BAJA","ACEPTABLE CON REVISIÓN"), IF(O40="BAJA",IF(COUNTIF( V40:V50,"Control/Acción Eficaz")>=1,"ACEPTABLE","BAJA"),)))), IF(COUNTA( V40:V50)-COUNTBLANK( V40:V50)=2, IF(O40="INACEPTABLE",IF(COUNTIF( V40:V50,"Control/Acción Eficaz")=2,"ACEPTABLE CON REVISIÓN", IF(OR(AND(COUNTIF( V40:V50,"Control/Acción Eficaz")=1,COUNTIF( V40:V50,"Control/Acción Satisfactorio")=1), AND(COUNTIF( V40:V50,"Control/Acción Eficaz")=1,COUNTIF( V40:V50,"Control/Acción No Eficaz")=1)),"SUSTANCIAL","INACEPTABLE")), IF(O40="SUSTANCIAL",IF(COUNTIF( V40:V50,"Control/Acción Eficaz")=2,"BAJA", IF(OR(AND(COUNTIF( V40:V50,"Control/Acción Eficaz")=1,COUNTIF( V40:V50,"Control/Acción Satisfactorio")=1), AND(COUNTIF( V40:V50,"Control/Acción Eficaz")=1,COUNTIF( V40:V50,"Control/Acción No Eficaz")=1)),"ACEPTABLE CON REVISIÓN ","SUSTANCIAL")), IF(O40="ACEPTABLE CON REVISIÓN",IF(COUNTIF( V40:V50,"Control/Acción Eficaz")=2,"ACEPTABLE", IF(OR(AND(COUNTIF( V40:V50,"Control/Acción Eficaz")=1,COUNTIF( V40:V50,"Control/Acción Satisfactorio")=1), AND(COUNTIF( V40:V50,"Control/Acción Eficaz")=1,COUNTIF( V40:V50,"Control/Acción No Eficaz")=1)),"BAJA","ACEPTABLE CON REVISIÓN")), IF(O40="BAJA",IF(COUNTIF( V40:V50,"Control/Acción Eficaz")>=2,"ACEPTABLE","BAJA"),)))), IF(COUNTA( V40:V50)-COUNTBLANK( V40:V50)>=3, IF(O40="INACEPTABLE", IF(COUNTBLANK( V40:V50)=COUNTA( V40:V50),"", IF(COUNTIF( V40:V50,"Control/Acción No Eficaz")>=2,"INACEPTABLE", IF(AND(COUNTIF( V40:V50,"Control/Acción No Eficaz")=0,COUNTIF( V40:V50,"Control/Acción Eficaz")>=2),"ACEPTABLE CON REVISIÓN ","SUSTANCIAL"))), IF(O40="SUSTANCIAL", IF(COUNTBLANK( V40:V50)=COUNTA( V40:V50),"", IF(COUNTIF( V40:V50,"Control/Acción No Eficaz")>=2,"SUSTANCIAL", IF(AND(COUNTIF( V40:V50,"Control/Acción No Eficaz")=0,COUNTIF( V40:V50,"Control/Acción Eficaz")>=2),"BAJA","ACEPTABLE CON REVISIÓN"))), IF(O40="ACEPTABLE CON REVISIÓN", IF(COUNTBLANK( V40:V50)=COUNTA( V40:V50),"", IF(COUNTIF( V40:V50,"Control/Acción No Eficaz")>=2,"ACEPTABLE CON REVISIÓN", IF(AND(COUNTIF( V40:V50,"Control/Acción No Eficaz")=0,COUNTIF( V40:V50,"Control/Acción Eficaz")>=2),"ACEPTABLE","BAJA"))), IF(O40="BAJA", IF(COUNTBLANK( V40:V50)=COUNTA( V40:V50),"", IF(AND(COUNTBLANK( V40:V50)<1,COUNTA( V40:V50)=1), IF(COUNTIF( V40:V50,"Control/Acción No Eficaz")>=2,"BAJA", IF(AND(COUNTIF( V40:V50,"Control/Acción No Eficaz")=0,COUNTIF( V40:V50,"Control/Acción Eficaz")>=2),"ACEPTABLE","BAJA")), IF(COUNTIF( V40:V50,"Control/Acción No Eficaz")>=2,"BAJA", IF(AND(COUNTIF( V40:V50,"Control/Acción No Eficaz")=0,COUNTIF( V40:V50,"Control/Acción Eficaz")>=2),"ACEPTABLE","BAJA")))), IF(COUNTIF( V40:V50,"")>=5,"",O40))))), "")))) -> ACEPTABLE CON REVISIÓN | Z40: OK | AA40: =E40 -> Seguridad
...

Sheet PARÁMETROS
A1: C. Probabilidad (A x B) | J1: Jerarquía del Control | K1: Calidad del Control
B2: A. Exposición | C2: 1 | D2: 2 | E2: 3 | F2: 4 | G2: 5 | H2: 6 | K2: Efectividad del Control | L2: C. Menor a 50% | M2: B. 50% y 80% | N2: A. Mayor 80% | P2: FAMILIA DE PELIGROS - SEGURIDAD | R2: FAMILIA DE RIESGOS - SEGURIDAD | T2: FAMILIA DE CONTROLES/ACCIONES - SEGURIDAD | V2: FAMILIA DE VERIFICADORES - SEGURIDAD | X2: Verificadores | Z2: FAMILIA DE ASPECTOS - MEDIO AMBIENTE | AB2: FAMILIA DE IMPACTOS - MEDIO AMBIENTE | AD2: FAMILIA DE CONTROLES - MEDIO AMBIENTE | AF2: FAMILIA DE VERIFICADORES - MEDIO AMBIENTE | AH2: FAMILIA PELIGROS - SALUD | AJ2: FAMILIA RIESGOS - SALUD | AL2: FAMILIA CONTROLES - SALUD | AN2: FAMILIA DE VERIFICADORES - SALUD | AP2: FAMILIA PELIGROS - LEGAL | AR2: FAMILIA RIESGOS - LEGAL | AT2: FAMILIA CONTROLES - LEGAL | AV2: FAMILIA VERIFICADORES - LEGAL | AX2: FAMILIA DE PELIGROS DSRC | AZ2: FAMILIA RIESGOS - DSRC | BB2: FAMILIA CONTROLES - DSRC | BD2: FAMILIA VERIFICADORES - DSRC | BF2: FAMILIA DE PELIGROS RG | BH2: FAMILIA RIESGOS - RG | BJ2: FAMILIA CONTROLES - RG | BL2: FAMILIA VERIFICADORES - RG | BN2: FAMILIA DE PELIGROS OPERACIONAL | BP2: FAMILIA RIESGOS OPERACIONAL | BR2: FAMILIA CONTROLES OPERACIONALES | BT2: FAMILIA VERIFICADORES OPERACIONALES | BV2: FAMILIA DE PELIGROS - FINANCIEROS | BX2: FAMILIA RIESGOS FINANCIEROS | BZ2: FAMILIA CONTROLES FINANCIEROS | CB2: FAMILIA VERIFICADORES FINANCIEROS
A3: B. Posibilidad | B3: 1 | C3: 5 | D3: 5 | E3: 4 | F3: 4 | G3: 3 | H3: 3 | K3: 6. Eliminación | L3: Control/Acción Satisfactorio | M3: Control/Acción Satisfactorio | N3: Control/Acción Eficaz | P3: Agentes Biológicos (animales, insectos, bacterias, virus, etc.) | R3: Aplastamiento | T3: Eliminación | V3: Planilla de vigencia de Autorizaciones, Permisos y Licencias (Gubernamentales, legales, normativos) | X3: Seguimiento a la Planilla de vigencia de cursos, autorizaciones, competencias y/o certificaciones de personas y equipos | Z3: Cambio de uso de suelo natural por actividad industrial, cultivos u otros | AB3: Agotamiento del recurso mineral/ reservas y recursos geológicos | AD3: Eliminación del proceso | AF3: Acreditaciones | AH3: A | AJ3: AA | AP3: LEGAL | AR3: LEGAL | AT3: LEGAL | AV3: LEGAL | AX3: Agotamiento de agua de pozos | AZ3: Bloqueos/Marchas/Amenazas/Demandas Sociales | BB3: RC.3.1.1. Fortalecer la cadena productiva de Quinua en comunidades del área de intervención en coordinación con el Consejo Consultivo mediante alianzas estratégicas | BD3: Publicación de indicadores | BF3: RELACIONALES GUBERNAMENTALES | BH3: RELACIONALES GUBERNAMENTALES | BJ3: RELACIONALES GUBERNAMENTALES | BN3: Conflictos sociales | BP3: Daño a la propiedad pública o privada | BR3: Alarmas / señales / advertencias | BT3: Verificadores Operacionales | BV3: financiero | BX3: financiero | BZ3: financiero | CB3: financiero
